<?xml version='1.0'?>
<sdf version='1.6'>
  <model name='m2wr'>
	  <include>
      <uri>model://realsense_model</uri>
      <pose>0.05 0 0.05 0 0 0</pose>
    </include>

    <joint name="realsense_joint" type="revolute">
      <parent>link_chassis</parent>
      <child>realsense2_camera::base_link</child>
      <axis>
        <limit>
          <lower>0</lower>
          <upper>0</upper>
        </limit>
        <xyz>0 0 1</xyz>
        <use_parent_model_frame>true</use_parent_model_frame>
      </axis>
    </joint>

	  
	  <link name='link_chassis'>
      <pose frame=''>0 0 0 0 -0 0</pose>
      <inertial>
        <pose frame=''>0 0 0.1 0 -0 0</pose>
        <mass>1.27</mass>
        <inertia>
          <ixx>0.0080696</ixx>
          <ixy>0</ixy>
          <ixz>0</ixz>
          <iyy>0.00986333</iyy>
          <iyz>0</iyz>
          <izz>0.00362433</izz>
        </inertia>
      </inertial>
      <collision name='link_chassis_fixed_joint_lump__collision_chassis_collision'>
        <pose frame=''>0 0 0 0 -0 0</pose>
        <geometry>
          <box>
            <size>0.26 0.16 0.093</size>
          </box>
        </geometry>
      </collision>
      <visual name='link_chassis_visual'>
        <pose frame=''>0 0 0 0 -0 0</pose>
        <geometry>
          <box>
            <size>0.26 0.16 0.093</size>
          </box>
        </geometry>
        <material>
          <script>
            <name>Gazebo/Black</name>
            <uri>file://media/materials/scripts/gazebo.material</uri>
          </script>
        </material>
      </visual>
      <gravity>1</gravity>
      <velocity_decay/>
    </link>
    <link name='link_left_wheel'>
      <pose frame=''>-0.085 -0.1025 -0.0256 0 -0 0</pose>
      <inertial>
        <pose frame=''>0 0 -0 0 1.5707 1.5707</pose>
        <mass>0.01</mass>
        <inertia>
          <ixx>0.000526667</ixx>
          <ixy>0</ixy>
          <ixz>0</ixz>
          <iyy>0.000526667</iyy>
          <iyz>0</iyz>
          <izz>0.001</izz>
        </inertia>
      </inertial>
      <collision name='link_left_wheel_fixed_joint_lump__link_right_wheel_collision_collision'>
        <pose frame=''>0 0 -0 3.14159 1.57079 -1.57089</pose>
        <geometry>
          <cylinder>
            <length>0.03</length>
            <radius>0.06</radius>
          </cylinder>
        </geometry>
      </collision>
      <visual name='link_left_wheel_visual_visual'>
        <pose frame=''>0 0 -0 3.14159 1.57079 -1.57089</pose>
        <geometry>
          <cylinder>
            <length>0.03</length>
            <radius>0.06</radius>
          </cylinder>
        </geometry>
        <material>
          <script>
            <name>Gazebo/Blue</name>
            <uri>file://media/materials/scripts/gazebo.material</uri>
          </script>
        </material>
      </visual>
      <gravity>1</gravity>
      <velocity_decay/>
    </link>
    <joint name='joint_left_wheel' type='revolute'>
      <child>link_left_wheel</child>
      <parent>link_chassis</parent>
      <axis>
	      <xyz>0 1 0</xyz>
        <limit effort="10000" velocity="1000">
          <lower>-1e+16</lower>
          <upper>1e+16</upper>
        </limit>
        <dynamics>
          <spring_reference>0</spring_reference>
          <spring_stiffness>0</spring_stiffness>
        </dynamics>
        <use_parent_model_frame>1</use_parent_model_frame>
      </axis>
    </joint>
    <link name='link_left_wheel_back'>
      <pose frame=''>0.085 -0.1025 -0.0256 0 -0 0</pose>
      <inertial>
        <pose frame=''>0 0 -0 0 1.5707 1.5707</pose>
        <mass>0.01</mass>
        <inertia>
          <ixx>0.000526667</ixx>
          <ixy>0</ixy>
          <ixz>0</ixz>
          <iyy>0.000526667</iyy>
          <iyz>0</iyz>
          <izz>0.001</izz>
        </inertia>
      </inertial>
      <collision name='link_left_wheel_back_fixed_joint_lump__link_right_wheel_collision_collision'>
        <pose frame=''>0 0 -0 3.14159 1.57079 -1.57089</pose>
        <geometry>
          <cylinder>
            <length>0.03</length>
            <radius>0.06</radius>
          </cylinder>
        </geometry>
      </collision>
      <visual name='link_left_wheel_back_visual_visual'>
        <pose frame=''>0 0 -0 3.14159 1.57079 -1.57089</pose>
        <geometry>
          <cylinder>
            <length>0.03</length>
            <radius>0.06</radius>
          </cylinder>
        </geometry>
        <material>
          <script>
            <name>Gazebo/Blue</name>
            <uri>file://media/materials/scripts/gazebo.material</uri>
          </script>
        </material>
      </visual>
      <gravity>1</gravity>
      <velocity_decay/>
    </link>
    <joint name='joint_left_wheel_back' type='revolute'>
      <child>link_left_wheel_back</child>
      <parent>link_chassis</parent>
      <axis>
        <xyz>0 1 0</xyz>
        <limit effort="10000" velocity="1000">
          <lower>-1e+16</lower>
          <upper>1e+16</upper>
        </limit>
        <dynamics>
          <spring_reference>0</spring_reference>
          <spring_stiffness>0</spring_stiffness>
        </dynamics>
        <use_parent_model_frame>1</use_parent_model_frame>
      </axis>
    </joint>
    <link name='link_right_wheel'>
      <pose frame=''>-0.085 0.1025 -0.0256 0 -0 0</pose>
      <inertial>
        <pose frame=''>0 0 -0 0 1.5707 1.5707</pose>
        <mass>0.01</mass>
        <inertia>
          <ixx>0.000526667</ixx>
          <ixy>0</ixy>
          <ixz>0</ixz>
          <iyy>0.000526667</iyy>
          <iyz>0</iyz>
          <izz>0.001</izz>
        </inertia>
      </inertial>
      <collision name='link_right_wheel_collision_collision'>
        <pose frame=''>0 0 -0 3.14159 1.57079 -1.57089</pose>
        <geometry>
          <cylinder>
            <length>0.03</length>
            <radius>0.06</radius>
          </cylinder>
        </geometry>
        <surface>
          <contact>
            <ode/>
          </contact>
          <friction>
            <ode/>
          </friction>
        </surface>
      </collision>
      <visual name='link_right_wheel_visual_visual'>
        <pose frame=''>0 0 -0 3.14159 1.57079 -1.57089</pose>
        <geometry>
          <cylinder>
            <length>0.03</length>
            <radius>0.06</radius>
          </cylinder>
        </geometry>
        <material>
          <script>
            <name>Gazebo/Blue</name>
            <uri>file://media/materials/scripts/gazebo.material</uri>
          </script>
        </material>
      </visual>
      <gravity>1</gravity>
      <velocity_decay/>
    </link>
    <joint name='joint_right_wheel' type='revolute'>
      <child>link_right_wheel</child>
      <parent>link_chassis</parent>
      <axis>
        <xyz>0 1 0</xyz>
        <limit effort="10000" velocity="1000">
          <lower>-1e+16</lower>
          <upper>1e+16</upper>
        </limit>
        <dynamics>
          <spring_reference>0</spring_reference>
          <spring_stiffness>0</spring_stiffness>
        </dynamics>
        <use_parent_model_frame>1</use_parent_model_frame>
      </axis>
    </joint>
    <link name='link_right_wheel_back'>
      <pose frame=''>0.085 0.1025 -0.0256 0 -0 0</pose>
      <inertial>
        <pose frame=''>0 0 -0 0 1.5707 1.5707</pose>
        <mass>0.01</mass>
        <inertia>
          <ixx>0.000526667</ixx>
          <ixy>0</ixy>
          <ixz>0</ixz>
          <iyy>0.000526667</iyy>
          <iyz>0</iyz>
          <izz>0.001</izz>
        </inertia>
      </inertial>
      <collision name='link_right_wheel_back_fixed_joint_lump__link_right_wheel_collision_collision'>
        <pose frame=''>0 0 -0 3.14159 1.57079 -1.57089</pose>
        <geometry>
          <cylinder>
            <length>0.03</length>
            <radius>0.06</radius>
          </cylinder>
        </geometry>
      </collision>
      <visual name='link_right_wheel_back_visual_visual'>
        <pose frame=''>0 0 -0 3.14159 1.57079 -1.57089</pose>
        <geometry>
          <cylinder>
            <length>0.03</length>
            <radius>0.06</radius>
          </cylinder>
        </geometry>
        <material>
          <script>
            <name>Gazebo/Blue</name>
            <uri>file://media/materials/scripts/gazebo.material</uri>
          </script>
        </material>
      </visual>
      <gravity>1</gravity>
      <velocity_decay/>
    </link>
    <joint name='joint_right_wheel_back' type='revolute'>
      <child>link_right_wheel_back</child>
      <parent>link_chassis</parent>
      <axis>
        <xyz>0 1 0</xyz>
        <limit effort="10000" velocity="1000">
          <lower>-1e+16</lower>
          <upper>1e+16</upper>
        </limit>
        <dynamics>
          <spring_reference>0</spring_reference>
          <spring_stiffness>0</spring_stiffness>
        </dynamics>
        <use_parent_model_frame>1</use_parent_model_frame>
      </axis>
    </joint>
    <static>0</static>

    <plugin name="turtlebot3_burger_controller" filename="libgazebo_ros_skid_steer_drive.so">
      <robotNamespace>/</robotNamespace>
      <commandTopic>cmd_vel2</commandTopic>
      <odometryTopic>odom</odometryTopic>
      <odometryFrame>odom</odometryFrame>
      <odometrySource>world</odometrySource>
      <publishOdomTF>true</publishOdomTF>
      <robotBaseFrame>link_chassis</robotBaseFrame>
      <publishWheelTF>false</publishWheelTF>
      <publishTf>true</publishTf>
      <publishWheelJointState>true</publishWheelJointState>
      <legacyMode>false</legacyMode>
      <updateRate>30</updateRate>
      <leftFrontJoint>joint_left_wheel</leftFrontJoint>
      <rightFrontJoint>joint_right_wheel</rightFrontJoint>
      <leftRearJoint>joint_left_wheel_back</leftRearJoint>
      <rightRearJoint>joint_right_wheel_back</rightRearJoint>
      <wheelSeparation>0.175</wheelSeparation>
      <wheelDiameter>0.12</wheelDiameter>
      <broadcastTF>1</broadcastTF>

      <!-- <wheelAcceleration>3</wheelAcceleration>
      <wheelTorque>200</wheelTorque> -->

      <torque>2</torque>
      <rosDebugLevel>na</rosDebugLevel>
    </plugin>

    <!-- <plugin name='skid_steer_drive_controller' filename='libgazebo_ros_skid_steer_drive.so'>
      <updateRate>20.0</updateRate>
      <robotNamespace>/</robotNamespace>
      <leftFrontJoint>joint_left_wheel</leftFrontJoint>
      <rightFrontJoint>joint_right_wheel</rightFrontJoint>
      <leftRearJoint>joint_left_wheel_back</leftRearJoint>
      <rightRearJoint>joint_right_wheel_back</rightRearJoint>
      <wheelSeparation>0.175</wheelSeparation>
      <wheelDiameter>0.12</wheelDiameter>
      <robotBaseFrame>link_chassis</robotBaseFrame>
      <torque>0.5</torque>
      <topicName>/cmd_vel</topicName>
      <broadcastTF>1</broadcastTF>
    </plugin> -->
  </model>
</sdf>
