<?xml version='1.0'?>
<sdf version='1.6'>
  <model name='shamir_and_realsense'>
    <link name='m2wr_with_rs::link_chassis'>
      <pose frame=''>0 0 0 0 -0 0</pose>
      <inertial>
        <pose frame=''>0 0 0.1 0 -0 0</pose>
        <mass>1.27</mass>
        <inertia>
          <ixx>0.0080696</ixx>
          <ixy>0</ixy>
          <ixz>0</ixz>
          <iyy>0.00986333</iyy>
          <iyz>0</iyz>
          <izz>0.00362433</izz>
        </inertia>
      </inertial>
      <gravity>1</gravity>
      <velocity_decay/>
      <self_collide>0</self_collide>
      <enable_wind>0</enable_wind>
      <kinematic>0</kinematic>
      <visual name='link_chassis_visual'>
        <pose frame=''>0 0 0 0 -0 0</pose>
        <geometry>
          <box>
            <size>0.26 0.16 0.093</size>
          </box>
        </geometry>
        <material>
          <script>
            <name>Gazebo/Black</name>
            <uri>file://media/materials/scripts/gazebo.material</uri>
          </script>
          <emissive>0 0 0 1</emissive>
          <shader type='vertex'>
            <normal_map>__default__</normal_map>
          </shader>
        </material>
        <transparency>0</transparency>
        <cast_shadows>1</cast_shadows>
      </visual>
      <collision name='link_chassis_fixed_joint_lump__collision_chassis_collision'>
        <laser_retro>0</laser_retro>
        <max_contacts>10</max_contacts>
        <pose frame=''>0 0 0 0 -0 0</pose>
        <geometry>
          <box>
            <size>0.26 0.16 0.093</size>
          </box>
        </geometry>
        <surface>
          <friction>
            <ode>
              <mu>1</mu>
              <mu2>1</mu2>
              <fdir1>0 0 0</fdir1>
              <slip1>0</slip1>
              <slip2>0</slip2>
            </ode>
            <torsional>
              <coefficient>1</coefficient>
              <patch_radius>0</patch_radius>
              <surface_radius>0</surface_radius>
              <use_patch_radius>1</use_patch_radius>
              <ode>
                <slip>0</slip>
              </ode>
            </torsional>
          </friction>
          <bounce>
            <restitution_coefficient>0</restitution_coefficient>
            <threshold>1e+06</threshold>
          </bounce>
          <contact>
            <collide_without_contact>0</collide_without_contact>
            <collide_without_contact_bitmask>1</collide_without_contact_bitmask>
            <collide_bitmask>1</collide_bitmask>
            <ode>
              <soft_cfm>0</soft_cfm>
              <soft_erp>0.2</soft_erp>
              <kp>1e+06</kp>
              <kd>1</kd>
              <max_vel>1</max_vel>
              <min_depth>0</min_depth>
            </ode>
            <bullet>
              <split_impulse>1</split_impulse>
              <split_impulse_penetration_threshold>-0.01</split_impulse_penetration_threshold>
              <soft_cfm>0</soft_cfm>
              <soft_erp>0.2</soft_erp>
              <kp>1e+06</kp>
              <kd>1</kd>
            </bullet>
          </contact>
        </surface>
      </collision>
    </link>
    <link name='m2wr_with_rs::link_left_wheel'>
      <pose frame=''>-0.085 -0.1025 -0.0256 0 -0 0</pose>
      <inertial>
        <pose frame=''>0 0 -0 -0 1.5707 1.5707</pose>
        <mass>0.01</mass>
        <inertia>
          <ixx>0.000526667</ixx>
          <ixy>0</ixy>
          <ixz>0</ixz>
          <iyy>0.000526667</iyy>
          <iyz>0</iyz>
          <izz>0.001</izz>
        </inertia>
      </inertial>
      <gravity>1</gravity>
      <velocity_decay/>
      <self_collide>0</self_collide>
      <enable_wind>0</enable_wind>
      <kinematic>0</kinematic>
      <visual name='link_left_wheel_visual_visual'>
        <pose frame=''>0 0 -0 -3.12268 1.57079 -1.55198</pose>
        <geometry>
          <cylinder>
            <length>0.03</length>
            <radius>0.06</radius>
          </cylinder>
        </geometry>
        <material>
          <script>
            <name>Gazebo/Blue</name>
            <uri>file://media/materials/scripts/gazebo.material</uri>
          </script>
          <emissive>0 0 0 1</emissive>
        </material>
        <transparency>0</transparency>
        <cast_shadows>1</cast_shadows>
      </visual>
      <collision name='link_left_wheel_fixed_joint_lump__link_right_wheel_collision_collision'>
        <laser_retro>0</laser_retro>
        <max_contacts>10</max_contacts>
        <pose frame=''>0 0 0 3.14159 1.57079 -1.57089</pose>
        <geometry>
          <cylinder>
            <radius>0.06</radius>
            <length>0.03</length>
          </cylinder>
        </geometry>
        <surface>
          <friction>
            <ode>
              <mu>1</mu>
              <mu2>1</mu2>
              <fdir1>0 0 0</fdir1>
              <slip1>0</slip1>
              <slip2>0</slip2>
            </ode>
            <torsional>
              <coefficient>1</coefficient>
              <patch_radius>0</patch_radius>
              <surface_radius>0</surface_radius>
              <use_patch_radius>1</use_patch_radius>
              <ode>
                <slip>0</slip>
              </ode>
            </torsional>
          </friction>
          <bounce>
            <restitution_coefficient>0</restitution_coefficient>
            <threshold>1e+06</threshold>
          </bounce>
          <contact>
            <collide_without_contact>0</collide_without_contact>
            <collide_without_contact_bitmask>1</collide_without_contact_bitmask>
            <collide_bitmask>1</collide_bitmask>
            <ode>
              <soft_cfm>0</soft_cfm>
              <soft_erp>0.2</soft_erp>
              <kp>1e+06</kp>
              <kd>1</kd>
              <max_vel>5</max_vel>
              <min_depth>0</min_depth>
            </ode>
            <bullet>
              <split_impulse>1</split_impulse>
              <split_impulse_penetration_threshold>-0.01</split_impulse_penetration_threshold>
              <soft_cfm>0</soft_cfm>
              <soft_erp>0.2</soft_erp>
              <kp>1e+06</kp>
              <kd>1</kd>
            </bullet>
          </contact>
        </surface>
      </collision>
    </link>
    <link name='m2wr_with_rs::link_left_wheel_back'>
      <pose frame=''>0.085 -0.1025 -0.0256 0 -0 0</pose>
      <inertial>
        <pose frame=''>0 0 0 -0 1.5707 1.5707</pose>
        <mass>0.01</mass>
        <inertia>
          <ixx>0.00052667</ixx>
          <ixy>0</ixy>
          <ixz>0</ixz>
          <iyy>0.00052667</iyy>
          <iyz>0</iyz>
          <izz>0.001</izz>
        </inertia>
      </inertial>
      <gravity>1</gravity>
      <velocity_decay/>
      <self_collide>0</self_collide>
      <enable_wind>0</enable_wind>
      <kinematic>0</kinematic>
      <visual name='link_left_wheel_back_visual_visual'>
        <pose frame=''>0 0 0 -3.12268 1.57079 -1.55198</pose>
        <geometry>
          <cylinder>
            <length>0.03</length>
            <radius>0.06</radius>
          </cylinder>
        </geometry>
        <material>
          <script>
            <name>Gazebo/Blue</name>
            <uri>file://media/materials/scripts/gazebo.material</uri>
          </script>
          <shader type='vertex'>
            <normal_map>__default__</normal_map>
          </shader>
        </material>
        <transparency>0</transparency>
        <cast_shadows>1</cast_shadows>
      </visual>
      <collision name='link_left_wheel_back_fixed_joint_lump__link_right_wheel_collision_collision'>
        <laser_retro>0</laser_retro>
        <max_contacts>10</max_contacts>
        <pose frame=''>0 0 0 3.14159 1.57079 -1.57089</pose>
        <geometry>
          <cylinder>
            <radius>0.06</radius>
            <length>0.03</length>
          </cylinder>
        </geometry>
        <surface>
          <friction>
            <ode>
              <mu>1</mu>
              <mu2>1</mu2>
              <fdir1>0 0 0</fdir1>
              <slip1>0</slip1>
              <slip2>0</slip2>
            </ode>
            <torsional>
              <coefficient>1</coefficient>
              <patch_radius>0</patch_radius>
              <surface_radius>0</surface_radius>
              <use_patch_radius>1</use_patch_radius>
              <ode>
                <slip>0</slip>
              </ode>
            </torsional>
          </friction>
          <bounce>
            <restitution_coefficient>0</restitution_coefficient>
            <threshold>1e+06</threshold>
          </bounce>
          <contact>
            <collide_without_contact>0</collide_without_contact>
            <collide_without_contact_bitmask>1</collide_without_contact_bitmask>
            <collide_bitmask>1</collide_bitmask>
            <ode>
              <soft_cfm>0</soft_cfm>
              <soft_erp>0.2</soft_erp>
              <kp>1e+06</kp>
              <kd>1</kd>
              <max_vel>5</max_vel>
              <min_depth>0</min_depth>
            </ode>
            <bullet>
              <split_impulse>1</split_impulse>
              <split_impulse_penetration_threshold>-0.01</split_impulse_penetration_threshold>
              <soft_cfm>0</soft_cfm>
              <soft_erp>0.2</soft_erp>
              <kp>1e+06</kp>
              <kd>1</kd>
            </bullet>
          </contact>
        </surface>
      </collision>
    </link>
    <link name='m2wr_with_rs::link_right_wheel'>
      <pose frame=''>-0.085 0.1025 -0.0256 0 -0 0</pose>
      <inertial>
        <pose frame=''>0 0 -0 -0 1.5707 1.5707</pose>
        <mass>0.01</mass>
        <inertia>
          <ixx>0.000526667</ixx>
          <ixy>0</ixy>
          <ixz>0</ixz>
          <iyy>0.000526667</iyy>
          <iyz>0</iyz>
          <izz>0.001</izz>
        </inertia>
      </inertial>
      <gravity>1</gravity>
      <velocity_decay/>
      <self_collide>0</self_collide>
      <enable_wind>0</enable_wind>
      <kinematic>0</kinematic>
      <visual name='link_right_wheel_visual_visual'>
        <pose frame=''>0 0 -0 -3.12268 1.57079 -1.55198</pose>
        <geometry>
          <cylinder>
            <length>0.03</length>
            <radius>0.06</radius>
          </cylinder>
        </geometry>
        <material>
          <script>
            <name>Gazebo/Blue</name>
            <uri>file://media/materials/scripts/gazebo.material</uri>
          </script>
        </material>
        <transparency>0</transparency>
        <cast_shadows>1</cast_shadows>
      </visual>
      <collision name='link_right_wheel_collision_collision'>
        <laser_retro>0</laser_retro>
        <max_contacts>10</max_contacts>
        <pose frame=''>0 0 0 3.14159 1.57079 -1.57089</pose>
        <geometry>
          <cylinder>
            <radius>0.06</radius>
            <length>0.03</length>
          </cylinder>
        </geometry>
        <surface>
          <friction>
            <ode>
              <mu>1</mu>
              <mu2>1</mu2>
              <fdir1>0 0 0</fdir1>
              <slip1>0</slip1>
              <slip2>0</slip2>
            </ode>
            <torsional>
              <coefficient>1</coefficient>
              <patch_radius>0</patch_radius>
              <surface_radius>0</surface_radius>
              <use_patch_radius>1</use_patch_radius>
              <ode>
                <slip>0</slip>
              </ode>
            </torsional>
          </friction>
          <bounce>
            <restitution_coefficient>0</restitution_coefficient>
            <threshold>1e+06</threshold>
          </bounce>
          <contact>
            <collide_without_contact>0</collide_without_contact>
            <collide_without_contact_bitmask>1</collide_without_contact_bitmask>
            <collide_bitmask>1</collide_bitmask>
            <ode>
              <soft_cfm>0</soft_cfm>
              <soft_erp>0.2</soft_erp>
              <kp>1e+06</kp>
              <kd>1</kd>
              <max_vel>5</max_vel>
              <min_depth>0</min_depth>
            </ode>
            <bullet>
              <split_impulse>1</split_impulse>
              <split_impulse_penetration_threshold>-0.01</split_impulse_penetration_threshold>
              <soft_cfm>0</soft_cfm>
              <soft_erp>0.2</soft_erp>
              <kp>1e+06</kp>
              <kd>1</kd>
            </bullet>
          </contact>
        </surface>
      </collision>
    </link>
    <link name='m2wr_with_rs::link_right_wheel_back'>
      <pose frame=''>0.085 0.1025 -0.0256 0 -0 0</pose>
      <inertial>
        <pose frame=''>0 0 -0 -0 1.5707 1.5707</pose>
        <mass>0.01</mass>
        <inertia>
          <ixx>0.000526667</ixx>
          <ixy>0</ixy>
          <ixz>0</ixz>
          <iyy>0.000526667</iyy>
          <iyz>0</iyz>
          <izz>0.001</izz>
        </inertia>
      </inertial>
      <gravity>1</gravity>
      <velocity_decay/>
      <self_collide>0</self_collide>
      <enable_wind>0</enable_wind>
      <kinematic>0</kinematic>
      <visual name='link_right_wheel_back_visual_visual'>
        <pose frame=''>0 0 -0 -3.12268 1.57079 -1.55198</pose>
        <geometry>
          <cylinder>
            <length>0.03</length>
            <radius>0.06</radius>
          </cylinder>
        </geometry>
        <material>
          <script>
            <name>Gazebo/Blue</name>
            <uri>file://media/materials/scripts/gazebo.material</uri>
          </script>
          <emissive>0 0 0 1</emissive>
        </material>
        <transparency>0</transparency>
        <cast_shadows>1</cast_shadows>
      </visual>
      <collision name='link_right_wheel_back_fixed_joint_lump__link_right_wheel_collision_collision'>
        <laser_retro>0</laser_retro>
        <max_contacts>10</max_contacts>
        <pose frame=''>0 0 0 3.14159 1.57079 -1.57089</pose>
        <geometry>
          <cylinder>
            <radius>0.06</radius>
            <length>0.03</length>
          </cylinder>
        </geometry>
        <surface>
          <friction>
            <ode>
              <mu>1</mu>
              <mu2>1</mu2>
              <fdir1>0 0 0</fdir1>
              <slip1>0</slip1>
              <slip2>0</slip2>
            </ode>
            <torsional>
              <coefficient>1</coefficient>
              <patch_radius>0</patch_radius>
              <surface_radius>0</surface_radius>
              <use_patch_radius>1</use_patch_radius>
              <ode>
                <slip>0</slip>
              </ode>
            </torsional>
          </friction>
          <bounce>
            <restitution_coefficient>0</restitution_coefficient>
            <threshold>1e+06</threshold>
          </bounce>
          <contact>
            <collide_without_contact>0</collide_without_contact>
            <collide_without_contact_bitmask>1</collide_without_contact_bitmask>
            <collide_bitmask>1</collide_bitmask>
            <ode>
              <soft_cfm>0</soft_cfm>
              <soft_erp>0.2</soft_erp>
              <kp>1e+06</kp>
              <kd>1</kd>
              <max_vel>5</max_vel>
              <min_depth>0</min_depth>
            </ode>
            <bullet>
              <split_impulse>1</split_impulse>
              <split_impulse_penetration_threshold>-0.01</split_impulse_penetration_threshold>
              <soft_cfm>0</soft_cfm>
              <soft_erp>0.2</soft_erp>
              <kp>1e+06</kp>
              <kd>1</kd>
            </bullet>
          </contact>
        </surface>
      </collision>
    </link>
    <model name='realsense2_camera'>
      <link name='base_link'>
        <pose frame=''>0 0 0.0175 0 -0 0</pose>
        <inertial>
          <pose frame=''>0 0.0175 0.0125 0 -0 0</pose>
          <mass>0.072</mass>
          <inertia>
            <ixx>0.00388124</ixx>
            <ixy>0</ixy>
            <ixz>0</ixz>
            <iyy>0.00049894</iyy>
            <iyz>0</iyz>
            <izz>0.00387926</izz>
          </inertia>
        </inertial>
        <collision name='base_link_fixed_joint_lump__camera_link_collision'>
          <pose frame=''>0 0 0.0125 0 -0 0</pose>
          <geometry>
            <box>
              <size>0.02505 0.09 0.025</size>
            </box>
          </geometry>
          <surface>
            <contact>
              <ode>
                <kp>1e+06</kp>
                <kd>1</kd>
              </ode>
            </contact>
            <friction>
              <ode>
                <mu2>1</mu2>
                <fdir1>0 0 0</fdir1>
              </ode>
              <torsional>
                <ode/>
              </torsional>
            </friction>
            <bounce/>
          </surface>
          <max_contacts>10</max_contacts>
        </collision>
        <visual name='base_link_fixed_joint_lump__camera_link_visual'>
          <pose frame=''>0.0149 0 0.0125 1.5708 -0 1.5708</pose>
          <geometry>
            <mesh>
              <scale>1 1 1</scale>
              <uri>model://realsense_model/meshes/d435.dae</uri>
            </mesh>
          </geometry>
          <material>
            <script>
              <uri>__default__</uri>
              <name>__default__</name>
            </script>
          </material>
        </visual>
        <gravity>1</gravity>
        <velocity_decay/>
        <self_collide>0</self_collide>
        <enable_wind>0</enable_wind>
        <kinematic>0</kinematic>
        <gravity>1</gravity>
        <sensor name='cameracolor' type='camera'>
          <camera name='camera'>
            <horizontal_fov>1.21126</horizontal_fov>
            <image>
              <width>192</width>
              <height>108</height>
              <format>RGB_INT8</format>
            </image>
            <clip>
              <near>0.1</near>
              <far>100</far>
            </clip>
            <noise>
              <type>gaussian</type>
              <mean>0</mean>
              <stddev>0.007</stddev>
            </noise>
          </camera>
          <always_on>1</always_on>
          <update_rate>30</update_rate>
          <visualize>1</visualize>
          <pose frame=''>0 0.0175 0.0125 0 -0 0</pose>
        </sensor>
        <sensor name='cameraired1' type='camera'>
          <camera name='camera'>
            <horizontal_fov>1.48702</horizontal_fov>
            <image>
              <width>640</width>
              <height>480</height>
              <format>L_INT8</format>
            </image>
            <clip>
              <near>0.1</near>
              <far>100</far>
            </clip>
            <noise>
              <type>gaussian</type>
              <mean>0</mean>
              <stddev>0.005</stddev>
            </noise>
          </camera>
          <always_on>1</always_on>
          <update_rate>90</update_rate>
          <visualize>0</visualize>
          <pose frame=''>0 -0.025 0.0125 0 -0 0</pose>
        </sensor>
        <sensor name='cameraired2' type='camera'>
          <camera name='camera'>
            <horizontal_fov>1.48702</horizontal_fov>
            <image>
              <width>640</width>
              <height>480</height>
              <format>L_INT8</format>
            </image>
            <clip>
              <near>0.1</near>
              <far>100</far>
            </clip>
            <noise>
              <type>gaussian</type>
              <mean>0</mean>
              <stddev>0.005</stddev>
            </noise>
          </camera>
          <always_on>1</always_on>
          <update_rate>90</update_rate>
          <visualize>0</visualize>
          <pose frame=''>0 0.025 0.0125 0 -0 0</pose>
        </sensor>
        <sensor name='cameradepth' type='depth'>
          <camera name='camera'>
            <horizontal_fov>1.48702</horizontal_fov>
            <image>
              <width>640</width>
              <height>480</height>
            </image>
            <clip>
              <near>0.1</near>
              <far>100</far>
            </clip>
            <noise>
              <type>gaussian</type>
              <mean>0</mean>
              <stddev>0.1</stddev>
            </noise>
          </camera>
          <always_on>1</always_on>
          <update_rate>90</update_rate>
          <visualize>0</visualize>
          <pose frame=''>0 0.0175 0.0125 0 -0 0</pose>
        </sensor>
        <sensor name='imu_sensor' type='imu'>
          <always_on>1</always_on>
          <update_rate>100</update_rate>
          <visualize>1</visualize>
          <topic>__default_topic__</topic>
          <plugin name='imu_plugin' filename='libgazebo_ros_imu_sensor.so'>
            <topicName>imu</topicName>
            <bodyName>imu_link</bodyName>
            <updateRateHZ>100.0</updateRateHZ>
            <gaussianNoise>0.0</gaussianNoise>
            <xyzOffset>0 0 0</xyzOffset>
            <rpyOffset>0 0 0</rpyOffset>
            <frameName>imu_link</frameName>
            <initialOrientationAsReference>0</initialOrientationAsReference>
          </plugin>
          <imu/>
        </sensor>
      </link>
      <static>0</static>
      <plugin name='camera' filename='librealsense_gazebo_plugin.so'>
        <prefix>camera</prefix>
        <depthUpdateRate>60.0</depthUpdateRate>
        <colorUpdateRate>60.0</colorUpdateRate>
        <infraredUpdateRate>60.0</infraredUpdateRate>
        <depthTopicName>depth/image_raw</depthTopicName>
        <depthCameraInfoTopicName>depth/camera_info</depthCameraInfoTopicName>
        <colorTopicName>color/image_raw</colorTopicName>
        <colorCameraInfoTopicName>color/camera_info</colorCameraInfoTopicName>
        <infrared1TopicName>infra1/image_raw</infrared1TopicName>
        <infrared1CameraInfoTopicName>infra1/camera_info</infrared1CameraInfoTopicName>
        <infrared2TopicName>infra2/image_raw</infrared2TopicName>
        <infrared2CameraInfoTopicName>infra2/camera_info</infrared2CameraInfoTopicName>
        <colorOpticalframeName>camera_color_optical_frame</colorOpticalframeName>
        <depthOpticalframeName>camera_depth_optical_frame</depthOpticalframeName>
        <infrared1OpticalframeName>camera_left_ir_optical_frame</infrared1OpticalframeName>
        <infrared2OpticalframeName>camera_right_ir_optical_frame</infrared2OpticalframeName>
        <rangeMinDepth>0.2</rangeMinDepth>
        <rangeMaxDepth>10.0</rangeMaxDepth>
        <pointCloud>0</pointCloud>
        <pointCloudTopicName>depth/points</pointCloudTopicName>
        <pointCloudCutoff>0.5</pointCloudCutoff>
      </plugin>
      <pose frame=''>0.110409 -0.005004 0.042572 0 0 0</pose>
    </model>
    <joint name='m2wr_with_rs::joint_left_wheel' type='revolute'>
      <parent>m2wr_with_rs::link_chassis</parent>
      <child>m2wr_with_rs::link_left_wheel</child>
      <pose frame=''>0 0 0 0 -0 0</pose>
      <axis>
        <xyz>0 1 0</xyz>
        <use_parent_model_frame>1</use_parent_model_frame>
        <limit>
          <lower>-1e+16</lower>
          <upper>1e+16</upper>
          <effort>-1</effort>
          <velocity>-1</velocity>
        </limit>
        <dynamics>
          <spring_reference>0</spring_reference>
          <spring_stiffness>0</spring_stiffness>
          <damping>0</damping>
          <friction>0</friction>
        </dynamics>
      </axis>
      <physics>
        <ode>
          <limit>
            <cfm>0</cfm>
            <erp>0.2</erp>
          </limit>
          <suspension>
            <cfm>0</cfm>
            <erp>0.2</erp>
          </suspension>
        </ode>
      </physics>
    </joint>
    <joint name='m2wr_with_rs::joint_left_wheel_back' type='revolute'>
      <parent>m2wr_with_rs::link_chassis</parent>
      <child>m2wr_with_rs::link_left_wheel_back</child>
      <pose frame=''>0 0 0 0 -0 0</pose>
      <axis>
        <xyz>0 1 0</xyz>
        <use_parent_model_frame>1</use_parent_model_frame>
        <limit>
          <lower>-1e+16</lower>
          <upper>1e+16</upper>
          <effort>-1</effort>
          <velocity>-1</velocity>
        </limit>
        <dynamics>
          <spring_reference>0</spring_reference>
          <spring_stiffness>0</spring_stiffness>
          <damping>0</damping>
          <friction>0</friction>
        </dynamics>
      </axis>
      <physics>
        <ode>
          <limit>
            <cfm>0</cfm>
            <erp>0.2</erp>
          </limit>
          <suspension>
            <cfm>0</cfm>
            <erp>0.2</erp>
          </suspension>
        </ode>
      </physics>
    </joint>
    <joint name='m2wr_with_rs::joint_right_wheel' type='revolute'>
      <parent>m2wr_with_rs::link_chassis</parent>
      <child>m2wr_with_rs::link_right_wheel</child>
      <pose frame=''>0 0 0 0 -0 0</pose>
      <axis>
        <xyz>0 1 0</xyz>
        <use_parent_model_frame>1</use_parent_model_frame>
        <limit>
          <lower>-1e+16</lower>
          <upper>1e+16</upper>
          <effort>-1</effort>
          <velocity>-1</velocity>
        </limit>
        <dynamics>
          <spring_reference>0</spring_reference>
          <spring_stiffness>0</spring_stiffness>
          <damping>0</damping>
          <friction>0</friction>
        </dynamics>
      </axis>
      <physics>
        <ode>
          <limit>
            <cfm>0</cfm>
            <erp>0.2</erp>
          </limit>
          <suspension>
            <cfm>0</cfm>
            <erp>0.2</erp>
          </suspension>
        </ode>
      </physics>
    </joint>
    <joint name='m2wr_with_rs::joint_right_wheel_back' type='revolute'>
      <parent>m2wr_with_rs::link_chassis</parent>
      <child>m2wr_with_rs::link_right_wheel_back</child>
      <pose frame=''>0 0 0 0 -0 0</pose>
      <axis>
        <xyz>0 1 0</xyz>
        <use_parent_model_frame>1</use_parent_model_frame>
        <limit>
          <lower>-1e+16</lower>
          <upper>1e+16</upper>
          <effort>-1</effort>
          <velocity>-1</velocity>
        </limit>
        <dynamics>
          <spring_reference>0</spring_reference>
          <spring_stiffness>0</spring_stiffness>
          <damping>0</damping>
          <friction>0</friction>
        </dynamics>
      </axis>
      <physics>
        <ode>
          <limit>
            <cfm>0</cfm>
            <erp>0.2</erp>
          </limit>
          <suspension>
            <cfm>0</cfm>
            <erp>0.2</erp>
          </suspension>
        </ode>
      </physics>
    </joint>
    <joint name='m2wr_with_rs::link_chassis_JOINT_0' type='fixed'>
      <parent>m2wr_with_rs::link_chassis</parent>
      <child>realsense2_camera::base_link</child>
      <pose frame=''>0 0 0 0 -0 0</pose>
      <physics>
        <ode>
          <limit>
            <cfm>0</cfm>
            <erp>0.2</erp>
          </limit>
          <suspension>
            <cfm>0</cfm>
            <erp>0.2</erp>
          </suspension>
        </ode>
      </physics>
    </joint>
    <static>0</static>
    <allow_auto_disable>1</allow_auto_disable>
    <plugin name='skid_steer_drive_controller' filename='libgazebo_ros_skid_steer_drive.so'>
      <updateRate>20.0</updateRate>
      <robotNamespace>/</robotNamespace>
      <leftFrontJoint>m2wr_with_rs::joint_left_wheel</leftFrontJoint>
      <rightFrontJoint>m2wr_with_rs::joint_right_wheel</rightFrontJoint>
      <leftRearJoint>m2wr_with_rs::joint_left_wheel_back</leftRearJoint>
      <rightRearJoint>m2wr_with_rs::joint_right_wheel_back</rightRearJoint>
      <wheelSeparation>0.175</wheelSeparation>
      <wheelDiameter>0.12</wheelDiameter>
      <robotBaseFrame>m2wr_with_rs::link_chassis</robotBaseFrame>
      <torque>0.5</torque>
      <topicName>/cmd_vel</topicName>
      <broadcastTF>0</broadcastTF>
    </plugin>
  </model>
</sdf>
